Workbook

Sheet Synthèse
A1: Inventaire Centreon – matrice de migration vers Zabbix
A2: Généré le 15/10/2026 12:58
A4: Source | B4: Export CLAPI : centreon_export_exemple.txt
A5: Hôtes | B5: 9
A6: Hôtes actifs | B6: 8
A7: Collecteurs (pollers) | B7: 2
A8: Services | B8: 35
A9: Services actifs | B9: 33
A10: Templates d'hôte (utilisés / total) | B10: 12 / 12
A11: Templates de service (utilisés / total) | B11: 20 / 21
A12: Commandes | B12: 17
A14: Proposition par template de service | B14: Nb templates | Nb services
A15: Migrer (template natif) | B15: 11 | 28
A16: Migrer (adapter) | B16: 2 | 3
A17: Ne pas migrer | B17: 3 | 1
A18: À analyser | B18: 2 | 3
A19: Hérité (pas d'action directe) | B19: 4 | 0
A21: Services par catégorie | B21: Nb services
A22: CPU | B22: 6
A23: Disque | B23: 5
A24: Mémoire | B24: 5
A25: Disponibilité | B25: 5
A26: Web | B26: 4
A27: Spécifique | B27: 3
A28: Matériel | B28: 2
A29: Base de données | B29: 1
A30: Processus | B30: 1
A31: Services Windows | B31: 1
A32: Passif / Dummy | B32: 1
A33: Réseau | B33: 1
A35: Services par stratégie | B35: Nb services
A36: Natif | B36: 28
A37: Adapter | B37: 3
A38: Développer | B38: 3
A39: Abandonner | B39: 1
A41: Top 15 des templates de service (par nombre de services)
A42: Template de service | B42: Nb services | C42: Nb hôtes | D42: Proposition | E42: Template Zabbix suggéré
A43: Base-Ping-LAN | B43: 5 | C43: 5 | D43: Migrer (template natif) | E43: ICMP Ping
A44: OS-Linux-Memory-SNMP-custom | B44: 5 | C44: 4 | D44: Migrer (template natif) | E44: Linux by SNMP
A45: OS-Linux-Cpu-SNMP-custom | B45: 4 | C45: 4 | D45: Migrer (template natif) | E45: Linux by SNMP
...

Sheet Matrice templates services
A1: Template de service | B1: Alias | C1: Chaîne d'héritage | D1: Template pack (racine) | E1: Templates d'hôte liés | F1: Commande | G1: Plugin | H1: Mode | I1: Arguments | J1: Nb services | K1: Nb services actifs | L1: Nb hôtes | M1: Nb services (hérités) | N1: Exemples d'hôtes | O1: Descriptions de service | P1: Catégorie | Q1: Template Zabbix suggéré | R1: Item Zabbix équivalent | S1: Stratégie | T1: Confiance | U1: Effort | V1: Priorité | W1: Justification | X1: Proposition | Y1: Décision finale | Z1: Template / item Zabbix cible | AA1: Commentaire
A2: Base-Ping-LAN | B2: Ping-LAN | C2: Base-Ping-LAN > generic-active-service-custom > generic-active-service > generic-service | D2: Base-Ping-LAN | F2: App-Monitoring-Centreon-Ping | J2: 5 | K2: 5 | L2: 5 | M2: 0 | N2: ups-dc1, srv-lnx-web01, srv-lnx-web02, srv-lnx-db01, srv-lnx-erp01 | O2: Ping | P2: Disponibilité | Q2: ICMP Ping | R2: icmpping / icmppingloss / icmppingsec | S2: Natif | T2: Élevée | U2: Faible | V2: Moyenne | W2: Équivalent Zabbix : ICMP Ping | X2: Migrer (template natif)
A3: OS-Linux-Memory-SNMP-custom | B3: Memory | C3: OS-Linux-Memory-SNMP-custom > generic-active-service-custom > generic-active-service > generic-service | D3: OS-Linux-Memory-SNMP-custom | E3: OS-Linux-SNMP-custom | F3: OS-Linux-SNMP-Memory | G3: os::linux::snmp::plugin | H3: memory | J3: 5 | K3: 4 | L3: 4 | M3: 0 | N3: srv-lnx-web01, srv-lnx-web02, srv-lnx-db01, srv-lnx-erp01 | O3: Memory, Old-Check | P3: Mémoire | Q3: Linux by SNMP | R3: vm.memory.* (SNMP) | S3: Natif | T3: Élevée | U3: Faible | V3: Basse | W3: Équivalent Zabbix : Linux by SNMP | X3: Migrer (template natif)
A4: OS-Linux-Cpu-SNMP-custom | B4: Cpu | C4: OS-Linux-Cpu-SNMP-custom > OS-Linux-Cpu-SNMP > generic-active-service-custom > generic-active-service > generic-service | D4: OS-Linux-Cpu-SNMP | E4: OS-Linux-SNMP-custom | F4: OS-Linux-SNMP-Cpu | G4: os::linux::snmp::plugin | H4: cpu | J4: 4 | K4: 4 | L4: 4 | M4: 0 | N4: srv-lnx-web01, srv-lnx-web02, srv-lnx-db01, srv-lnx-erp01 | O4: Cpu | P4: CPU | Q4: Linux by SNMP | R4: system.cpu.util[...] (SNMP) | S4: Natif | T4: Élevée | U4: Faible | V4: Basse | W4: Équivalent Zabbix : Linux by SNMP | X4: Migrer (template natif)
A5: OS-Linux-Disk-Generic-Name-SNMP-custom | B5: Disk-Generic-Name | C5: OS-Linux-Disk-Generic-Name-SNMP-custom > generic-active-service-custom > generic-active-service > generic-service | D5: OS-Linux-Disk-Generic-Name-SNMP-custom | E5: OS-Linux-SNMP-custom | F5: OS-Linux-SNMP-Disk-Name | G5: os::linux::snmp::plugin | H5: storage | J5: 3 | K5: 3 | L5: 3 | M5: 0 | N5: srv-lnx-web01, srv-lnx-web02, srv-lnx-db01 | O5: Disk-/, Disk-/var/lib/mysql | P5: Disque | Q5: Linux by SNMP | R5: LLD vfs.fs (SNMP) | S5: Natif | T5: Élevée | U5: Faible | V5: Basse | W5: Équivalent Zabbix : Linux by SNMP | X5: Migrer (template natif)
A6: App-Protocol-HTTP-Response-Time-custom | B6: HTTP-Response-Time | C6: App-Protocol-HTTP-Response-Time-custom > generic-active-service-custom > generic-active-service > generic-service | D6: App-Protocol-HTTP-Response-Time-custom | F6: App-Protocol-HTTP-Response | G6: apps::protocols::http::plugin | H6: response | J6: 2 | K6: 2 | L6: 2 | M6: 0 | N6: srv-lnx-web01, srv-lnx-web02 | O6: HTTP-Response-Time | P6: Web | Q6: Website by Browser | R6: Scénario Web / web.page.get[] / item HTTP agent | S6: Adapter | T6: Élevée | U6: Moyen | V6: Basse | W6: Équivalent Zabbix : Website by Browser | X6: Migrer (adapter)
A7: App-Webserver-Apache-Requests-custom | B7: Requests | C7: App-Webserver-Apache-Requests-custom > generic-active-service-custom > generic-active-service > generic-service | D7: App-Webserver-Apache-Requests-custom | E7: App-Webserver-Apache-ServerStatus-custom | F7: App-Webserver-Apache-Requests | G7: apps::apache::serverstatus::plugin | H7: requests | J7: 2 | K7: 2 | L7: 2 | M7: 0 | N7: srv-lnx-web01, srv-lnx-web02 | O7: Apache-Requests | P7: Web | Q7: Apache by HTTP | R7: apache.* | S7: Natif | T7: Élevée | U7: Faible | V7: Basse | W7: Équivalent Zabbix : Apache by HTTP | X7: Migrer (template natif)
A8: ERP-Batch-Nocturne | B8: Batch ERP | C8: ERP-Batch-Nocturne > generic-active-service-custom > generic-active-service > generic-service | D8: ERP-Batch-Nocturne | F8: check_erp_batch | I8: !NIGHTLY!3600!7200 | J8: 2 | K8: 2 | L8: 1 | M8: 0 | N8: srv-lnx-erp01 | O8: Batch-Nocturne, Batch-Mensuel | P8: Spécifique | R8: UserParameter / script externe / plugin agent 2 | S8: Développer | T8: Faible | U8: Élevé | V8: Basse | W8: Check spécifique : analyser le script et son besoin métier | X8: À analyser
A9: Net-Cisco-Standard-Environment-SNMP-custom | B9: Environment | C9: Net-Cisco-Standard-Environment-SNMP-custom > generic-active-service-custom > generic-active-service > generic-service | D9: Net-Cisco-Standard-Environment-SNMP-custom | E9: Net-Cisco-Standard-SNMP-custom | F9: Net-Cisco-Standard-SNMP-Environment | G9: network::cisco::standard::snmp::plugin | H9: environment | J9: 2 | K9: 1 | L9: 2 | M9: 0 | N9: sw-core-01, sw-acc-02 | O9: Environment | P9: Matériel | Q9: (template constructeur SNMP) | R9: LLD capteurs / ventilateurs / alimentations | S9: Natif | T9: Moyenne | U9: Faible | V9: Basse | W9: Équivalent Zabbix : (template constructeur SNMP) | X9: Migrer (template natif)
A10: OS-Windows-Cpu-SNMP-custom | B10: Cpu | C10: OS-Windows-Cpu-SNMP-custom > generic-active-service-custom > generic-active-service > generic-service | D10: OS-Windows-Cpu-SNMP-custom | E10: OS-Windows-SNMP-custom | F10: OS-Windows-SNMP-Cpu | G10: os::windows::snmp::plugin | H10: cpu | J10: 2 | K10: 2 | L10: 2 | M10: 0 | N10: srv-win-ad01, srv-win-file01 | O10: Cpu | P10: CPU | Q10: Windows by SNMP | R10: system.cpu.util (SNMP) | S10: Natif | T10: Élevée | U10: Faible | V10: Basse | W10: Équivalent Zabbix : Windows by SNMP | X10: Migrer (template natif)
A11: OS-Windows-Disk-Generic-Name-SNMP-custom | B11: Disk | C11: OS-Windows-Disk-Generic-Name-SNMP-custom > generic-active-service-custom > generic-active-service > generic-service | D11: OS-Windows-Disk-Generic-Name-SNMP-custom | E11: OS-Windows-SNMP-custom | F11: OS-Windows-SNMP-Storage | G11: os::windows::snmp::plugin | H11: storage | J11: 2 | K11: 2 | L11: 2 | M11: 0 | N11: srv-win-ad01, srv-win-file01 | O11: Disk-C, Disk-D | P11: Disque | Q11: Windows by SNMP | R11: LLD vfs.fs (SNMP) | S11: Natif | T11: Élevée | U11: Faible | V11: Basse | W11: Équivalent Zabbix : Windows by SNMP | X11: Migrer (template natif)
A12: (aucun template) check_erp_batch | F12: check_erp_batch | I12: !LICENCE!30!7 | J12: 1 | K12: 1 | L12: 1 | M12: 0 | N12: srv-lnx-erp01 | O12: Licence-ERP | P12: Spécifique | R12: UserParameter / script externe / plugin agent 2 | S12: Développer | T12: Faible | U12: Élevé | V12: Basse | W12: Check spécifique : analyser le script et son besoin métier | X12: À analyser
A13: App-DB-MySQL-Connection-Time-custom | B13: Connection-Time | C13: App-DB-MySQL-Connection-Time-custom > generic-active-service-custom > generic-active-service > generic-service | D13: App-DB-MySQL-Connection-Time-custom | E13: App-DB-MySQL-custom | F13: App-DB-MySQL-Connections | G13: database::mysql::plugin | H13: connection-time | J13: 1 | K13: 1 | L13: 1 | M13: 0 | N13: srv-lnx-db01 | O13: MySQL-Connection-Time | P13: Base de données | Q13: MySQL by Zabbix agent 2 | R13: mysql.* | S13: Natif | T13: Élevée | U13: Faible | V13: Basse | W13: Équivalent Zabbix : MySQL by Zabbix agent 2 | X13: Migrer (template natif)
A14: Net-Cisco-Standard-Traffic-Generic-Name-SNMP-custom | B14: Traffic | C14: Net-Cisco-Standard-Traffic-Generic-Name-SNMP-custom > generic-active-service-custom > generic-active-service > generic-service | D14: Net-Cisco-Standard-Traffic-Generic-Name-SNMP-custom | F14: Net-Cisco-Standard-SNMP-Traffic-Name | G14: network::cisco::standard::snmp::plugin | H14: interfaces | J14: 1 | K14: 1 | L14: 1 | M14: 0 | N14: sw-core-01 | O14: Traffic-Gi1/0/1 | P14: Réseau | Q14: (template constructeur SNMP) | R14: LLD net.if (SNMP) | S14: Natif | T14: Élevée | U14: Faible | V14: Basse | W14: Équivalent Zabbix : (template constructeur SNMP) | X14: Migrer (template natif)
A15: OS-Linux-Process-Generic-SNMP-custom | B15: Process-Generic | C15: OS-Linux-Process-Generic-SNMP-custom > generic-active-service-custom > generic-active-service > generic-service | D15: OS-Linux-Process-Generic-SNMP-custom | F15: OS-Linux-SNMP-Processcount | G15: os::linux::snmp::plugin | H15: processcount | J15: 1 | K15: 1 | L15: 1 | M15: 0 | N15: srv-lnx-db01 | O15: Process-mysqld | P15: Processus | R15: Item SNMP hrSWRunName (à créer) | S15: Adapter | T15: Moyenne | U15: Moyen | V15: Basse | W15: Équivalent Zabbix : Item SNMP hrSWRunName (à créer) | X15: Migrer (adapter)
A16: OS-Windows-Services-NRPE-custom | B16: Services | C16: OS-Windows-Services-NRPE-custom > generic-active-service-custom > generic-active-service > generic-service | D16: OS-Windows-Services-NRPE-custom | F16: OS-Windows-NSClient-Services | J16: 1 | K16: 1 | L16: 1 | M16: 0 | N16: srv-win-ad01 | O16: Service-NTDS | P16: Services Windows | Q16: Windows by Zabbix agent | R16: LLD service.discovery / service.info[] | S16: Natif | T16: Élevée | U16: Faible | V16: Basse | W16: Équivalent Zabbix : Windows by Zabbix agent | X16: Migrer (template natif)
A17: Passive-Trap-Dummy | B17: Trap passif | C17: Passive-Trap-Dummy > generic-service | D17: Passive-Trap-Dummy | F17: check_centreon_dummy | J17: 1 | K17: 1 | L17: 1 | M17: 0 | N17: srv-win-file01 | O17: Trap-Sauvegarde | P17: Passif / Dummy | R17: Item trapper (zabbix_sender) si encore utile | S17: Abandonner | T17: Moyenne | U17: Nul | V17: Basse | W17: Équivalent Zabbix : Item trapper (zabbix_sender) si encore utile | X17: Ne pas migrer
A18: generic-service | B18: generic-service | C18: generic-service | D18: generic-service | J18: 0 | K18: 0 | L18: 0 | M18: 34 | U18: - | V18: - | W18: Parent de templates utilisés (34 services) | X18: Hérité (pas d'action directe)
A19: generic-active-service | B19: generic-active-service | C19: generic-active-service > generic-service | D19: generic-active-service | J19: 0 | K19: 0 | L19: 0 | M19: 33 | U19: - | V19: - | W19: Parent de templates utilisés (33 services) | X19: Hérité (pas d'action directe)
A20: generic-active-service-custom | B20: generic-active-service-custom | C20: generic-active-service-custom > generic-active-service > generic-service | D20: generic-active-service-custom | J20: 0 | K20: 0 | L20: 0 | M20: 33 | U20: - | V20: - | W20: Parent de templates utilisés (33 services) | X20: Hérité (pas d'action directe)
A21: OS-Linux-Cpu-SNMP | B21: Cpu | C21: OS-Linux-Cpu-SNMP > generic-active-service-custom > generic-active-service > generic-service | D21: OS-Linux-Cpu-SNMP | F21: OS-Linux-SNMP-Cpu | G21: os::linux::snmp::plugin | H21: cpu | J21: 0 | K21: 0 | L21: 0 | M21: 4 | P21: CPU | Q21: Linux by SNMP | R21: system.cpu.util[...] (SNMP) | S21: Natif | T21: Élevée | U21: - | V21: - | W21: Parent de templates utilisés (4 services) | X21: Hérité (pas d'action directe)
A22: OS-Linux-Ntp-SNMP-custom | B22: Ntp | C22: OS-Linux-Ntp-SNMP-custom > generic-active-service-custom > generic-active-service > generic-service | D22: OS-Linux-Ntp-SNMP-custom | J22: 0 | K22: 0 | L22: 0 | M22: 0 | P22: Temps | R22: net.udp.service[ntp] | S22: Adapter | T22: Faible | U22: - | V22: - | W22: Template inutilisé | X22: Ne pas migrer
A23: OS-Linux-Traffic-Generic-Name-SNMP-custom | B23: Traffic-Generic-Name | C23: OS-Linux-Traffic-Generic-Name-SNMP-custom > generic-active-service-custom > generic-active-service > generic-service | D23: OS-Linux-Traffic-Generic-Name-SNMP-custom | F23: OS-Linux-SNMP-Traffic-Name | G23: os::linux::snmp::plugin | H23: interfaces | J23: 0 | K23: 0 | L23: 0 | M23: 0 | P23: Réseau | Q23: Linux by SNMP | R23: LLD net.if (SNMP) | S23: Natif | T23: Élevée | U23: - | V23: - | W23: Template inutilisé | X23: Ne pas migrer

Sheet Matrice templates hôtes
A1: Template d'hôte | B1: Alias | C1: Parents | D1: Chaîne complète | E1: Templates de service liés | F1: Nb hôtes (direct) | G1: Nb hôtes (total) | H1: Nb services issus du template | I1: Exemples d'hôtes | J1: Template Zabbix suggéré | K1: Stratégie | L1: Confiance | M1: Priorité | N1: Justification | O1: Proposition | P1: Décision finale | Q1: Template Zabbix cible | R1: Commentaire
A2: OS-Linux-SNMP-custom | B2: Template Linux SNMP | C2: OS-Linux-SNMP, generic-active-host-custom | D2: OS-Linux-SNMP-custom > OS-Linux-SNMP > generic-active-host > generic-host > generic-active-host-custom | E2: OS-Linux-Cpu-SNMP-custom, OS-Linux-Memory-SNMP-custom, OS-Linux-Disk-Generic-Name-SNMP-custom | F2: 4 | G2: 4 | H2: 12 | I2: srv-lnx-web01, srv-lnx-web02, srv-lnx-db01, srv-lnx-erp01 | J2: Linux by SNMP | K2: Natif | L2: Élevée | M2: Basse | N2: Équivalent Zabbix : Linux by SNMP | O2: Migrer (template natif)
A3: App-Webserver-Apache-ServerStatus-custom | B3: Apache | D3: App-Webserver-Apache-ServerStatus-custom | E3: App-Webserver-Apache-Requests-custom | F3: 2 | G3: 2 | H3: 2 | I3: srv-lnx-web01, srv-lnx-web02 | J3: Apache by HTTP | K3: Natif | L3: Élevée | M3: Basse | N3: Équivalent Zabbix : Apache by HTTP | O3: Migrer (template natif)
A4: Net-Cisco-Standard-SNMP-custom | B4: Cisco standard | C4: generic-active-host-custom | D4: Net-Cisco-Standard-SNMP-custom > generic-active-host-custom > generic-active-host > generic-host | E4: Net-Cisco-Standard-Environment-SNMP-custom | F4: 2 | G4: 2 | H4: 2 | I4: sw-core-01, sw-acc-02 | J4: Cisco IOS by SNMP | K4: Natif | L4: Élevée | M4: Basse | N4: Équivalent Zabbix : Cisco IOS by SNMP | O4: Migrer (template natif)
A5: OS-Windows-SNMP-custom | B5: Template Windows SNMP | C5: generic-active-host-custom | D5: OS-Windows-SNMP-custom > generic-active-host-custom > generic-active-host > generic-host | E5: OS-Windows-Cpu-SNMP-custom, OS-Windows-Disk-Generic-Name-SNMP-custom | F5: 2 | G5: 2 | H5: 4 | I5: srv-win-ad01, srv-win-file01 | J5: Windows by SNMP | K5: Natif | L5: Élevée | M5: Basse | N5: Équivalent Zabbix : Windows by SNMP | O5: Migrer (template natif)
A6: App-DB-MySQL-custom | B6: MySQL | D6: App-DB-MySQL-custom | E6: App-DB-MySQL-Connection-Time-custom | F6: 1 | G6: 1 | H6: 1 | I6: srv-lnx-db01 | J6: MySQL by Zabbix agent 2 | K6: Natif | L6: Élevée | M6: Basse | N6: Équivalent Zabbix : MySQL by Zabbix agent 2 | O6: Migrer (template natif)
A7: ERP-Applicatif | B7: Serveur ERP maison | D7: ERP-Applicatif | F7: 1 | G7: 1 | H7: 0 | I7: srv-lnx-erp01 | K7: À analyser | L7: Faible | M7: Basse | N7: Aucune correspondance connue : check spécifique | O7: À analyser
A8: HW-Ups-Standard-Rfc1628-SNMP-custom | B8: Onduleur RFC1628 | C8: generic-active-host-custom | D8: HW-Ups-Standard-Rfc1628-SNMP-custom > generic-active-host-custom > generic-active-host > generic-host | F8: 1 | G8: 1 | H8: 0 | I8: ups-dc1 | J8: APC UPS by SNMP | K8: Natif | L8: Faible | M8: Basse | N8: Selon constructeur (APC, Eaton : UPS by SNMP générique) | O8: Migrer (template natif)
A9: OS-Windows-NSClient-05-NRPE-custom | B9: Windows NSClient NRPE | C9: generic-active-host-custom | D9: OS-Windows-NSClient-05-NRPE-custom > generic-active-host-custom > generic-active-host > generic-host | F9: 1 | G9: 1 | H9: 0 | I9: srv-win-ad01 | J9: Windows by Zabbix agent | K9: Natif | L9: Élevée | M9: Basse | N9: Remplacer NSClient++ par l'agent Zabbix | O9: Migrer (template natif)
A10: generic-active-host | B10: generic-active-host | C10: generic-host | D10: generic-active-host > generic-host | F10: 0 | G10: 9 | H10: 0 | I10: srv-lnx-web01, srv-lnx-web02, srv-lnx-db01, srv-lnx-erp01, srv-win-ad01 ... | J10: ICMP Ping | K10: Natif | L10: Moyenne | M10: Moyenne | N10: Hérité par 9 hôte(s) via d'autres templates | O10: Hérité (pas d'action directe)
A11: generic-active-host-custom | B11: generic-active-host-custom | C11: generic-active-host | D11: generic-active-host-custom > generic-active-host > generic-host | F11: 0 | G11: 9 | H11: 0 | I11: srv-lnx-web01, srv-lnx-web02, srv-lnx-db01, srv-lnx-erp01, srv-win-ad01 ... | J11: ICMP Ping | K11: Natif | L11: Moyenne | M11: Moyenne | N11: Hérité par 9 hôte(s) via d'autres templates | O11: Hérité (pas d'action directe)
A12: generic-host | B12: generic-host | D12: generic-host | F12: 0 | G12: 9 | H12: 0 | I12: srv-lnx-web01, srv-lnx-web02, srv-lnx-db01, srv-lnx-erp01, srv-win-ad01 ... | J12: ICMP Ping | K12: Natif | L12: Moyenne | M12: Moyenne | N12: Hérité par 9 hôte(s) via d'autres templates | O12: Hérité (pas d'action directe)
A13: OS-Linux-SNMP | B13: Template Linux SNMP | C13: generic-active-host | D13: OS-Linux-SNMP > generic-active-host > generic-host | F13: 0 | G13: 4 | H13: 0 | I13: srv-lnx-web01, srv-lnx-web02, srv-lnx-db01, srv-lnx-erp01 | J13: Linux by SNMP | K13: Natif | L13: Élevée | M13: Basse | N13: Hérité par 4 hôte(s) via d'autres templates | O13: Hérité (pas d'action directe)

Sheet Hôtes
A1: Hôte | B1: Alias | C1: Adresse | D1: Collecteur | E1: Groupes d'hôtes | F1: Templates (directs) | G1: Templates (tous) | H1: Actif | I1: Nb services | J1: Nb services actifs | K1: Nb services spécifiques | L1: Interface Zabbix suggérée | M1: Templates Zabbix suggérés | N1: Proxy Zabbix suggéré | O1: Proposition | P1: Décision finale | Q1: Commentaire
A2: srv-lnx-db01 | B2: Base MySQL | C2: 10.0.10.21 | D2: Poller-DC1 | E2: HG-Linux | F2: OS-Linux-SNMP-custom, App-DB-MySQL-custom | G2: OS-Linux-SNMP-custom, OS-Linux-SNMP, generic-active-host, generic-host, generic-active-host-custom, App-DB-MySQL-custom | H2: Oui | I2: 6 | J2: 6 | K2: 0 | L2: Agent + SNMP | M2: Linux by SNMP, MySQL by Zabbix agent 2, ICMP Ping | N2: Poller-DC1 | O2: Migrer
A3: srv-lnx-erp01 | B3: Serveur ERP | C3: 10.0.10.31 | D3: Poller-DC2 | E3: HG-Linux | F3: OS-Linux-SNMP-custom, ERP-Applicatif | G3: OS-Linux-SNMP-custom, OS-Linux-SNMP, generic-active-host, generic-host, generic-active-host-custom, ERP-Applicatif | H3: Oui | I3: 6 | J3: 6 | K3: 3 | L3: SNMP | M3: Linux by SNMP, ICMP Ping | N3: Poller-DC2 | O3: Migrer
A4: srv-lnx-web01 | B4: Frontal web 1 | C4: 10.0.10.11 | D4: Poller-DC1 | E4: HG-Linux, HG-Web | F4: OS-Linux-SNMP-custom, App-Webserver-Apache-ServerStatus-custom | G4: OS-Linux-SNMP-custom, OS-Linux-SNMP, generic-active-host, generic-host, generic-active-host-custom, App-Webserver-Apache-ServerStatus-custom | H4: Oui | I4: 7 | J4: 6 | K4: 0 | L4: SNMP | M4: Linux by SNMP, Apache by HTTP, ICMP Ping | N4: Poller-DC1 | O4: Migrer
A5: srv-lnx-web02 | B5: Frontal web 2 | C5: 10.0.10.12 | D5: Poller-DC1 | E5: HG-Linux, HG-Web | F5: OS-Linux-SNMP-custom, App-Webserver-Apache-ServerStatus-custom | G5: OS-Linux-SNMP-custom, OS-Linux-SNMP, generic-active-host, generic-host, generic-active-host-custom, App-Webserver-Apache-ServerStatus-custom | H5: Oui | I5: 6 | J5: 6 | K5: 0 | L5: SNMP | M5: Linux by SNMP, Apache by HTTP, ICMP Ping | N5: Poller-DC1 | O5: Migrer
A6: srv-win-ad01 | B6: Controleur AD | C6: 10.0.20.11 | D6: Poller-DC1 | E6: HG-Windows | F6: OS-Windows-SNMP-custom, OS-Windows-NSClient-05-NRPE-custom | G6: OS-Windows-SNMP-custom, generic-active-host-custom, generic-active-host, generic-host, OS-Windows-NSClient-05-NRPE-custom | H6: Oui | I6: 3 | J6: 3 | K6: 0 | L6: Agent + SNMP | M6: Windows by SNMP, Windows by Zabbix agent | N6: Poller-DC1 | O6: Migrer
A7: srv-win-file01 | B7: Serveur fichiers | C7: 10.0.20.12 | D7: Poller-DC2 | E7: HG-Windows | F7: OS-Windows-SNMP-custom | G7: OS-Windows-SNMP-custom, generic-active-host-custom, generic-active-host, generic-host | H7: Oui | I7: 3 | J7: 3 | K7: 0 | L7: SNMP | M7: Windows by SNMP | N7: Poller-DC2 | O7: Migrer
A8: sw-acc-02 | B8: Switch acces (decom) | C8: 10.0.0.2 | D8: Poller-DC2 | E8: HG-Reseau | F8: Net-Cisco-Standard-SNMP-custom | G8: Net-Cisco-Standard-SNMP-custom, generic-active-host-custom, generic-active-host, generic-host | H8: Non | I8: 1 | J8: 0 | K8: 0 | L8: SNMP | M8: Cisco IOS by SNMP | N8: Poller-DC2 | O8: Ne pas migrer
A9: sw-core-01 | B9: Switch coeur | C9: 10.0.0.1 | D9: Poller-DC1 | E9: HG-Reseau | F9: Net-Cisco-Standard-SNMP-custom | G9: Net-Cisco-Standard-SNMP-custom, generic-active-host-custom, generic-active-host, generic-host | H9: Oui | I9: 2 | J9: 2 | K9: 0 | L9: SNMP | M9: Cisco IOS by SNMP | N9: Poller-DC1 | O9: Migrer
A10: ups-dc1 | B10: Onduleur DC1 | C10: 10.0.0.50 | D10: Poller-DC1 | F10: HW-Ups-Standard-Rfc1628-SNMP-custom | G10: HW-Ups-Standard-Rfc1628-SNMP-custom, generic-active-host-custom, generic-active-host, generic-host | H10: Oui | I10: 1 | J10: 1 | K10: 0 | L10: SNMP | M10: APC UPS by SNMP, ICMP Ping | N10: Poller-DC1 | O10: Migrer

Sheet Services
A1: Hôte | B1: Adresse | C1: Collecteur | D1: Service | E1: Actif | F1: Hérité du groupe | G1: Template de service | H1: Chaîne d'héritage | I1: Commande | J1: Plugin | K1: Mode | L1: Arguments | M1: Ligne de commande résolue | N1: Catégorie | O1: Template Zabbix suggéré | P1: Item Zabbix équivalent | Q1: Stratégie | R1: Proposition | S1: Décision (template) | T1: Décision (service) | U1: Décision effective | V1: Commentaire
A2: srv-lnx-db01 | B2: 10.0.10.21 | C2: Poller-DC1 | D2: Cpu | E2: Oui | G2: OS-Linux-Cpu-SNMP-custom | H2: OS-Linux-Cpu-SNMP-custom > OS-Linux-Cpu-SNMP > generic-active-service-custom > generic-active-service > generic-service | I2: OS-Linux-SNMP-Cpu | J2: os::linux::snmp::plugin | K2: cpu | M2: $CENTREONPLUGINS$/centreon_linux_snmp.pl --plugin=os::linux::snmp::plugin --mode=cpu --hostname=$HOSTADDRESS$ --snmp-version='2c' --snmp-community=******** --warning-average='80' --critical-average='90' | N2: CPU | O2: Linux by SNMP | P2: system.cpu.util[...] (SNMP) | Q2: Natif | R2: Migrer (template natif) | S2: =IFERROR(IF(INDEX('Matrice templates services'!$Y$2:$Y$23,MATCH($G2,'Matrice templates services'!$A$2:$A$23,0))<>"",INDEX('Matrice templates services'!$Y$2:$Y$23,MATCH($G2,'Matrice templates services'!$A$2:$A$23,0)),INDEX('Matrice templates services'!$X$2:$X$23,MATCH($G2,'Matrice templates services'!$A$2:$A$23,0))),"") | U2: =IF(T2<>"",T2,IF(E2="Non","Ne pas migrer",S2))
A3: srv-lnx-db01 | B3: 10.0.10.21 | C3: Poller-DC1 | D3: Disk-/var/lib/mysql | E3: Oui | G3: OS-Linux-Disk-Generic-Name-SNMP-custom | H3: OS-Linux-Disk-Generic-Name-SNMP-custom > generic-active-service-custom > generic-active-service > generic-service | I3: OS-Linux-SNMP-Disk-Name | J3: os::linux::snmp::plugin | K3: storage | M3: $CENTREONPLUGINS$/centreon_linux_snmp.pl --plugin=os::linux::snmp::plugin --mode=storage --hostname=$HOSTADDRESS$ --snmp-version='2c' --snmp-community=******** --storage='/var/lib/mysql' --name --warning-usage='$_SERVICEWARNING$' --critical-usage='$_SERVICECRITICAL$' | N3: Disque | O3: Linux by SNMP | P3: LLD vfs.fs (SNMP) | Q3: Natif | R3: Migrer (template natif) | S3: =IFERROR(IF(INDEX('Matrice templates services'!$Y$2:$Y$23,MATCH($G3,'Matrice templates services'!$A$2:$A$23,0))<>"",INDEX('Matrice templates services'!$Y$2:$Y$23,MATCH($G3,'Matrice templates services'!$A$2:$A$23,0)),INDEX('Matrice templates services'!$X$2:$X$23,MATCH($G3,'Matrice templates services'!$A$2:$A$23,0))),"") | U3: =IF(T3<>"",T3,IF(E3="Non","Ne pas migrer",S3))
A4: srv-lnx-db01 | B4: 10.0.10.21 | C4: Poller-DC1 | D4: Memory | E4: Oui | G4: OS-Linux-Memory-SNMP-custom | H4: OS-Linux-Memory-SNMP-custom > generic-active-service-custom > generic-active-service > generic-service | I4: OS-Linux-SNMP-Memory | J4: os::linux::snmp::plugin | K4: memory | M4: $CENTREONPLUGINS$/centreon_linux_snmp.pl --plugin=os::linux::snmp::plugin --mode=memory --hostname=$HOSTADDRESS$ --snmp-version='2c' --snmp-community=******** --warning-usage='$_SERVICEWARNING$' --critical-usage='$_SERVICECRITICAL$' | N4: Mémoire | O4: Linux by SNMP | P4: vm.memory.* (SNMP) | Q4: Natif | R4: Migrer (template natif) | S4: =IFERROR(IF(INDEX('Matrice templates services'!$Y$2:$Y$23,MATCH($G4,'Matrice templates services'!$A$2:$A$23,0))<>"",INDEX('Matrice templates services'!$Y$2:$Y$23,MATCH($G4,'Matrice templates services'!$A$2:$A$23,0)),INDEX('Matrice templates services'!$X$2:$X$23,MATCH($G4,'Matrice templates services'!$A$2:$A$23,0))),"") | U4: =IF(T4<>"",T4,IF(E4="Non","Ne pas migrer",S4))
A5: srv-lnx-db01 | B5: 10.0.10.21 | C5: Poller-DC1 | D5: MySQL-Connection-Time | E5: Oui | G5: App-DB-MySQL-Connection-Time-custom | H5: App-DB-MySQL-Connection-Time-custom > generic-active-service-custom > generic-active-service > generic-service | I5: App-DB-MySQL-Connections | J5: database::mysql::plugin | K5: connection-time | M5: $CENTREONPLUGINS$/centreon_mysql.pl --plugin=database::mysql::plugin --mode=connection-time --host=$HOSTADDRESS$ --username='centreon' --password=******** | N5: Base de données | O5: MySQL by Zabbix agent 2 | P5: mysql.* | Q5: Natif | R5: Migrer (template natif) | S5: =IFERROR(IF(INDEX('Matrice templates services'!$Y$2:$Y$23,MATCH($G5,'Matrice templates services'!$A$2:$A$23,0))<>"",INDEX('Matrice templates services'!$Y$2:$Y$23,MATCH($G5,'Matrice templates services'!$A$2:$A$23,0)),INDEX('Matrice templates services'!$X$2:$X$23,MATCH($G5,'Matrice templates services'!$A$2:$A$23,0))),"") | U5: =IF(T5<>"",T5,IF(E5="Non","Ne pas migrer",S5))
A6: srv-lnx-db01 | B6: 10.0.10.21 | C6: Poller-DC1 | D6: Ping | E6: Oui | F6: HG-Linux | G6: Base-Ping-LAN | H6: Base-Ping-LAN > generic-active-service-custom > generic-active-service > generic-service | I6: App-Monitoring-Centreon-Ping | M6: $USER1$/check_icmp -H $HOSTADDRESS$ -n 5 -w 200,20% -c 400,50% | N6: Disponibilité | O6: ICMP Ping | P6: icmpping / icmppingloss / icmppingsec | Q6: Natif | R6: Migrer (template natif) | S6: =IFERROR(IF(INDEX('Matrice templates services'!$Y$2:$Y$23,MATCH($G6,'Matrice templates services'!$A$2:$A$23,0))<>"",INDEX('Matrice templates services'!$Y$2:$Y$23,MATCH($G6,'Matrice templates services'!$A$2:$A$23,0)),INDEX('Matrice templates services'!$X$2:$X$23,MATCH($G6,'Matrice templates services'!$A$2:$A$23,0))),"") | U6: =IF(T6<>"",T6,IF(E6="Non","Ne pas migrer",S6))
A7: srv-lnx-db01 | B7: 10.0.10.21 | C7: Poller-DC1 | D7: Process-mysqld | E7: Oui | G7: OS-Linux-Process-Generic-SNMP-custom | H7: OS-Linux-Process-Generic-SNMP-custom > generic-active-service-custom > generic-active-service > generic-service | I7: OS-Linux-SNMP-Processcount | J7: os::linux::snmp::plugin | K7: processcount | M7: $CENTREONPLUGINS$/centreon_linux_snmp.pl --plugin=os::linux::snmp::plugin --mode=processcount --hostname=$HOSTADDRESS$ --snmp-version='2c' --snmp-community=******** --process-name='mysqld' | N7: Processus | P7: Item SNMP hrSWRunName (à créer) | Q7: Adapter | R7: Migrer (adapter) | S7: =IFERROR(IF(INDEX('Matrice templates services'!$Y$2:$Y$23,MATCH($G7,'Matrice templates services'!$A$2:$A$23,0))<>"",INDEX('Matrice templates services'!$Y$2:$Y$23,MATCH($G7,'Matrice templates services'!$A$2:$A$23,0)),INDEX('Matrice templates services'!$X$2:$X$23,MATCH($G7,'Matrice templates services'!$A$2:$A$23,0))),"") | U7: =IF(T7<>"",T7,IF(E7="Non","Ne pas migrer",S7))
A8: srv-lnx-erp01 | B8: 10.0.10.31 | C8: Poller-DC2 | D8: Batch-Mensuel | E8: Oui | G8: ERP-Batch-Nocturne | H8: ERP-Batch-Nocturne > generic-active-service-custom > generic-active-service > generic-service | I8: check_erp_batch | L8: !MONTHLY!7200!14400 | M8: $USER2$/check_erp_batch.sh -H $HOSTADDRESS$ -j MONTHLY -w 7200 -c 14400 | N8: Spécifique | P8: UserParameter / script externe / plugin agent 2 | Q8: Développer | R8: À analyser | S8: =IFERROR(IF(INDEX('Matrice templates services'!$Y$2:$Y$23,MATCH($G8,'Matrice templates services'!$A$2:$A$23,0))<>"",INDEX('Matrice templates services'!$Y$2:$Y$23,MATCH($G8,'Matrice templates services'!$A$2:$A$23,0)),INDEX('Matrice templates services'!$X$2:$X$23,MATCH($G8,'Matrice templates services'!$A$2:$A$23,0))),"") | U8: =IF(T8<>"",T8,IF(E8="Non","Ne pas migrer",S8))
A9: srv-lnx-erp01 | B9: 10.0.10.31 | C9: Poller-DC2 | D9: Batch-Nocturne | E9: Oui | G9: ERP-Batch-Nocturne | H9: ERP-Batch-Nocturne > generic-active-service-custom > generic-active-service > generic-service | I9: check_erp_batch | L9: !NIGHTLY!3600!7200 | M9: $USER2$/check_erp_batch.sh -H $HOSTADDRESS$ -j NIGHTLY -w 3600 -c 7200 | N9: Spécifique | P9: UserParameter / script externe / plugin agent 2 | Q9: Développer | R9: À analyser | S9: =IFERROR(IF(INDEX('Matrice templates services'!$Y$2:$Y$23,MATCH($G9,'Matrice templates services'!$A$2:$A$23,0))<>"",INDEX('Matrice templates services'!$Y$2:$Y$23,MATCH($G9,'Matrice templates services'!$A$2:$A$23,0)),INDEX('Matrice templates services'!$X$2:$X$23,MATCH($G9,'Matrice templates services'!$A$2:$A$23,0))),"") | U9: =IF(T9<>"",T9,IF(E9="Non","Ne pas migrer",S9))
A10: srv-lnx-erp01 | B10: 10.0.10.31 | C10: Poller-DC2 | D10: Cpu | E10: Oui | G10: OS-Linux-Cpu-SNMP-custom | H10: OS-Linux-Cpu-SNMP-custom > OS-Linux-Cpu-SNMP > generic-active-service-custom > generic-active-service > generic-service | I10: OS-Linux-SNMP-Cpu | J10: os::linux::snmp::plugin | K10: cpu | M10: $CENTREONPLUGINS$/centreon_linux_snmp.pl --plugin=os::linux::snmp::plugin --mode=cpu --hostname=$HOSTADDRESS$ --snmp-version='2c' --snmp-community=******** --warning-average='80' --critical-average='90' | N10: CPU | O10: Linux by SNMP | P10: system.cpu.util[...] (SNMP) | Q10: Natif | R10: Migrer (template natif) | S10: =IFERROR(IF(INDEX('Matrice templates services'!$Y$2:$Y$23,MATCH($G10,'Matrice templates services'!$A$2:$A$23,0))<>"",INDEX('Matrice templates services'!$Y$2:$Y$23,MATCH($G10,'Matrice templates services'!$A$2:$A$23,0)),INDEX('Matrice templates services'!$X$2:$X$23,MATCH($G10,'Matrice templates services'!$A$2:$A$23,0))),"") | U10: =IF(T10<>"",T10,IF(E10="Non","Ne pas migrer",S10))
A11: srv-lnx-erp01 | B11: 10.0.10.31 | C11: Poller-DC2 | D11: Licence-ERP | E11: Oui | G11: (aucun template) check_erp_batch | I11: check_erp_batch | L11: !LICENCE!30!7 | M11: $USER2$/check_erp_batch.sh -H $HOSTADDRESS$ -j LICENCE -w 30 -c 7 | N11: Spécifique | P11: UserParameter / script externe / plugin agent 2 | Q11: Développer | R11: À analyser | S11: =IFERROR(IF(INDEX('Matrice templates services'!$Y$2:$Y$23,MATCH($G11,'Matrice templates services'!$A$2:$A$23,0))<>"",INDEX('Matrice templates services'!$Y$2:$Y$23,MATCH($G11,'Matrice templates services'!$A$2:$A$23,0)),INDEX('Matrice templates services'!$X$2:$X$23,MATCH($G11,'Matrice templates services'!$A$2:$A$23,0))),"") | U11: =IF(T11<>"",T11,IF(E11="Non","Ne pas migrer",S11))
A12: srv-lnx-erp01 | B12: 10.0.10.31 | C12: Poller-DC2 | D12: Memory | E12: Oui | G12: OS-Linux-Memory-SNMP-custom | H12: OS-Linux-Memory-SNMP-custom > generic-active-service-custom > generic-active-service > generic-service | I12: OS-Linux-SNMP-Memory | J12: os::linux::snmp::plugin | K12: memory | M12: $CENTREONPLUGINS$/centreon_linux_snmp.pl --plugin=os::linux::snmp::plugin --mode=memory --hostname=$HOSTADDRESS$ --snmp-version='2c' --snmp-community=******** --warning-usage='$_SERVICEWARNING$' --critical-usage='$_SERVICECRITICAL$' | N12: Mémoire | O12: Linux by SNMP | P12: vm.memory.* (SNMP) | Q12: Natif | R12: Migrer (template natif) | S12: =IFERROR(IF(INDEX('Matrice templates services'!$Y$2:$Y$23,MATCH($G12,'Matrice templates services'!$A$2:$A$23,0))<>"",INDEX('Matrice templates services'!$Y$2:$Y$23,MATCH($G12,'Matrice templates services'!$A$2:$A$23,0)),INDEX('Matrice templates services'!$X$2:$X$23,MATCH($G12,'Matrice templates services'!$A$2:$A$23,0))),"") | U12: =IF(T12<>"",T12,IF(E12="Non","Ne pas migrer",S12))
A13: srv-lnx-erp01 | B13: 10.0.10.31 | C13: Poller-DC2 | D13: Ping | E13: Oui | F13: HG-Linux | G13: Base-Ping-LAN | H13: Base-Ping-LAN > generic-active-service-custom > generic-active-service > generic-service | I13: App-Monitoring-Centreon-Ping | M13: $USER1$/check_icmp -H $HOSTADDRESS$ -n 5 -w 200,20% -c 400,50% | N13: Disponibilité | O13: ICMP Ping | P13: icmpping / icmppingloss / icmppingsec | Q13: Natif | R13: Migrer (template natif) | S13: =IFERROR(IF(INDEX('Matrice templates services'!$Y$2:$Y$23,MATCH($G13,'Matrice templates services'!$A$2:$A$23,0))<>"",INDEX('Matrice templates services'!$Y$2:$Y$23,MATCH($G13,'Matrice templates services'!$A$2:$A$23,0)),INDEX('Matrice templates services'!$X$2:$X$23,MATCH($G13,'Matrice templates services'!$A$2:$A$23,0))),"") | U13: =IF(T13<>"",T13,IF(E13="Non","Ne pas migrer",S13))
A14: srv-lnx-web01 | B14: 10.0.10.11 | C14: Poller-DC1 | D14: Apache-Requests | E14: Oui | G14: App-Webserver-Apache-Requests-custom | H14: App-Webserver-Apache-Requests-custom > generic-active-service-custom > generic-active-service > generic-service | I14: App-Webserver-Apache-Requests | J14: apps::apache::serverstatus::plugin | K14: requests | M14: $CENTREONPLUGINS$/centreon_apache_serverstatus.pl --plugin=apps::apache::serverstatus::plugin --mode=requests --hostname=$HOSTADDRESS$ | N14: Web | O14: Apache by HTTP | P14: apache.* | Q14: Natif | R14: Migrer (template natif) | S14: =IFERROR(IF(INDEX('Matrice templates services'!$Y$2:$Y$23,MATCH($G14,'Matrice templates services'!$A$2:$A$23,0))<>"",INDEX('Matrice templates services'!$Y$2:$Y$23,MATCH($G14,'Matrice templates services'!$A$2:$A$23,0)),INDEX('Matrice templates services'!$X$2:$X$23,MATCH($G14,'Matrice templates services'!$A$2:$A$23,0))),"") | U14: =IF(T14<>"",T14,IF(E14="Non","Ne pas migrer",S14))
A15: srv-lnx-web01 | B15: 10.0.10.11 | C15: Poller-DC1 | D15: Cpu | E15: Oui | G15: OS-Linux-Cpu-SNMP-custom | H15: OS-Linux-Cpu-SNMP-custom > OS-Linux-Cpu-SNMP > generic-active-service-custom > generic-active-service > generic-service | I15: OS-Linux-SNMP-Cpu | J15: os::linux::snmp::plugin | K15: cpu | M15: $CENTREONPLUGINS$/centreon_linux_snmp.pl --plugin=os::linux::snmp::plugin --mode=cpu --hostname=$HOSTADDRESS$ --snmp-version='2c' --snmp-community=******** --warning-average='80' --critical-average='90' | N15: CPU | O15: Linux by SNMP | P15: system.cpu.util[...] (SNMP) | Q15: Natif | R15: Migrer (template natif) | S15: =IFERROR(IF(INDEX('Matrice templates services'!$Y$2:$Y$23,MATCH($G15,'Matrice templates services'!$A$2:$A$23,0))<>"",INDEX('Matrice templates services'!$Y$2:$Y$23,MATCH($G15,'Matrice templates services'!$A$2:$A$23,0)),INDEX('Matrice templates services'!$X$2:$X$23,MATCH($G15,'Matrice templates services'!$A$2:$A$23,0))),"") | U15: =IF(T15<>"",T15,IF(E15="Non","Ne pas migrer",S15))
A16: srv-lnx-web01 | B16: 10.0.10.11 | C16: Poller-DC1 | D16: Disk-/ | E16: Oui | G16: OS-Linux-Disk-Generic-Name-SNMP-custom | H16: OS-Linux-Disk-Generic-Name-SNMP-custom > generic-active-service-custom > generic-active-service > generic-service | I16: OS-Linux-SNMP-Disk-Name | J16: os::linux::snmp::plugin | K16: storage | M16: $CENTREONPLUGINS$/centreon_linux_snmp.pl --plugin=os::linux::snmp::plugin --mode=storage --hostname=$HOSTADDRESS$ --snmp-version='2c' --snmp-community=******** --storage='/' --name --warning-usage='$_SERVICEWARNING$' --critical-usage='$_SERVICECRITICAL$' | N16: Disque | O16: Linux by SNMP | P16: LLD vfs.fs (SNMP) | Q16: Natif | R16: Migrer (template natif) | S16: =IFERROR(IF(INDEX('Matrice templates services'!$Y$2:$Y$23,MATCH($G16,'Matrice templates services'!$A$2:$A$23,0))<>"",INDEX('Matrice templates services'!$Y$2:$Y$23,MATCH($G16,'Matrice templates services'!$A$2:$A$23,0)),INDEX('Matrice templates services'!$X$2:$X$23,MATCH($G16,'Matrice templates services'!$A$2:$A$23,0))),"") | U16: =IF(T16<>"",T16,IF(E16="Non","Ne pas migrer",S16))
A17: srv-lnx-web01 | B17: 10.0.10.11 | C17: Poller-DC1 | D17: HTTP-Response-Time | E17: Oui | F17: HG-Web | G17: App-Protocol-HTTP-Response-Time-custom | H17: App-Protocol-HTTP-Response-Time-custom > generic-active-service-custom > generic-active-service > generic-service | I17: App-Protocol-HTTP-Response | J17: apps::protocols::http::plugin | K17: response | M17: $CENTREONPLUGINS$/centreon_protocol_http.pl --plugin=apps::protocols::http::plugin --mode=response --hostname=$_SERVICEURLHOST$ --urlpath='/health' --ssl-opt='SSL_verify_mode => SSL_VERIFY_NONE' | N17: Web | O17: Website by Browser | P17: Scénario Web / web.page.get[] / item HTTP agent | Q17: Adapter | R17: Migrer (adapter) | S17: =IFERROR(IF(INDEX('Matrice templates services'!$Y$2:$Y$23,MATCH($G17,'Matrice templates services'!$A$2:$A$23,0))<>"",INDEX('Matrice templates services'!$Y$2:$Y$23,MATCH($G17,'Matrice templates services'!$A$2:$A$23,0)),INDEX('Matrice templates services'!$X$2:$X$23,MATCH($G17,'Matrice templates services'!$A$2:$A$23,0))),"") | U17: =IF(T17<>"",T17,IF(E17="Non","Ne pas migrer",S17))
A18: srv-lnx-web01 | B18: 10.0.10.11 | C18: Poller-DC1 | D18: Memory | E18: Oui | G18: OS-Linux-Memory-SNMP-custom | H18: OS-Linux-Memory-SNMP-custom > generic-active-service-custom > generic-active-service > generic-service | I18: OS-Linux-SNMP-Memory | J18: os::linux::snmp::plugin | K18: memory | M18: $CENTREONPLUGINS$/centreon_linux_snmp.pl --plugin=os::linux::snmp::plugin --mode=memory --hostname=$HOSTADDRESS$ --snmp-version='2c' --snmp-community=******** --warning-usage='$_SERVICEWARNING$' --critical-usage='$_SERVICECRITICAL$' | N18: Mémoire | O18: Linux by SNMP | P18: vm.memory.* (SNMP) | Q18: Natif | R18: Migrer (template natif) | S18: =IFERROR(IF(INDEX('Matrice templates services'!$Y$2:$Y$23,MATCH($G18,'Matrice templates services'!$A$2:$A$23,0))<>"",INDEX('Matrice templates services'!$Y$2:$Y$23,MATCH($G18,'Matrice templates services'!$A$2:$A$23,0)),INDEX('Matrice templates services'!$X$2:$X$23,MATCH($G18,'Matrice templates services'!$A$2:$A$23,0))),"") | U18: =IF(T18<>"",T18,IF(E18="Non","Ne pas migrer",S18))
A19: srv-lnx-web01 | B19: 10.0.10.11 | C19: Poller-DC1 | D19: Old-Check | E19: Non | G19: OS-Linux-Memory-SNMP-custom | H19: OS-Linux-Memory-SNMP-custom > generic-active-service-custom > generic-active-service > generic-service | I19: OS-Linux-SNMP-Memory | J19: os::linux::snmp::plugin | K19: memory | M19: $CENTREONPLUGINS$/centreon_linux_snmp.pl --plugin=os::linux::snmp::plugin --mode=memory --hostname=$HOSTADDRESS$ --snmp-version='2c' --snmp-community=******** --warning-usage='$_SERVICEWARNING$' --critical-usage='$_SERVICECRITICAL$' | N19: Mémoire | O19: Linux by SNMP | P19: vm.memory.* (SNMP) | Q19: Natif | R19: Ne pas migrer | S19: =IFERROR(IF(INDEX('Matrice templates services'!$Y$2:$Y$23,MATCH($G19,'Matrice templates services'!$A$2:$A$23,0))<>"",INDEX('Matrice templates services'!$Y$2:$Y$23,MATCH($G19,'Matrice templates services'!$A$2:$A$23,0)),INDEX('Matrice templates services'!$X$2:$X$23,MATCH($G19,'Matrice templates services'!$A$2:$A$23,0))),"") | U19: =IF(T19<>"",T19,IF(E19="Non","Ne pas migrer",S19))
A20: srv-lnx-web01 | B20: 10.0.10.11 | C20: Poller-DC1 | D20: Ping | E20: Oui | F20: HG-Linux | G20: Base-Ping-LAN | H20: Base-Ping-LAN > generic-active-service-custom > generic-active-service > generic-service | I20: App-Monitoring-Centreon-Ping | M20: $USER1$/check_icmp -H $HOSTADDRESS$ -n 5 -w 200,20% -c 400,50% | N20: Disponibilité | O20: ICMP Ping | P20: icmpping / icmppingloss / icmppingsec | Q20: Natif | R20: Migrer (template natif) | S20: =IFERROR(IF(INDEX('Matrice templates services'!$Y$2:$Y$23,MATCH($G20,'Matrice templates services'!$A$2:$A$23,0))<>"",INDEX('Matrice templates services'!$Y$2:$Y$23,MATCH($G20,'Matrice templates services'!$A$2:$A$23,0)),INDEX('Matrice templates services'!$X$2:$X$23,MATCH($G20,'Matrice templates services'!$A$2:$A$23,0))),"") | U20: =IF(T20<>"",T20,IF(E20="Non","Ne pas migrer",S20))
A21: srv-lnx-web02 | B21: 10.0.10.12 | C21: Poller-DC1 | D21: Apache-Requests | E21: Oui | G21: App-Webserver-Apache-Requests-custom | H21: App-Webserver-Apache-Requests-custom > generic-active-service-custom > generic-active-service > generic-service | I21: App-Webserver-Apache-Requests | J21: apps::apache::serverstatus::plugin | K21: requests | M21: $CENTREONPLUGINS$/centreon_apache_serverstatus.pl --plugin=apps::apache::serverstatus::plugin --mode=requests --hostname=$HOSTADDRESS$ | N21: Web | O21: Apache by HTTP | P21: apache.* | Q21: Natif | R21: Migrer (template natif) | S21: =IFERROR(IF(INDEX('Matrice templates services'!$Y$2:$Y$23,MATCH($G21,'Matrice templates services'!$A$2:$A$23,0))<>"",INDEX('Matrice templates services'!$Y$2:$Y$23,MATCH($G21,'Matrice templates services'!$A$2:$A$23,0)),INDEX('Matrice templates services'!$X$2:$X$23,MATCH($G21,'Matrice templates services'!$A$2:$A$23,0))),"") | U21: =IF(T21<>"",T21,IF(E21="Non","Ne pas migrer",S21))
A22: srv-lnx-web02 | B22: 10.0.10.12 | C22: Poller-DC1 | D22: Cpu | E22: Oui | G22: OS-Linux-Cpu-SNMP-custom | H22: OS-Linux-Cpu-SNMP-custom > OS-Linux-Cpu-SNMP > generic-active-service-custom > generic-active-service > generic-service | I22: OS-Linux-SNMP-Cpu | J22: os::linux::snmp::plugin | K22: cpu | M22: $CENTREONPLUGINS$/centreon_linux_snmp.pl --plugin=os::linux::snmp::plugin --mode=cpu --hostname=$HOSTADDRESS$ --snmp-version='2c' --snmp-community=******** --warning-average='80' --critical-average='90' | N22: CPU | O22: Linux by SNMP | P22: system.cpu.util[...] (SNMP) | Q22: Natif | R22: Migrer (template natif) | S22: =IFERROR(IF(INDEX('Matrice templates services'!$Y$2:$Y$23,MATCH($G22,'Matrice templates services'!$A$2:$A$23,0))<>"",INDEX('Matrice templates services'!$Y$2:$Y$23,MATCH($G22,'Matrice templates services'!$A$2:$A$23,0)),INDEX('Matrice templates services'!$X$2:$X$23,MATCH($G22,'Matrice templates services'!$A$2:$A$23,0))),"") | U22: =IF(T22<>"",T22,IF(E22="Non","Ne pas migrer",S22))
A23: srv-lnx-web02 | B23: 10.0.10.12 | C23: Poller-DC1 | D23: Disk-/ | E23: Oui | G23: OS-Linux-Disk-Generic-Name-SNMP-custom | H23: OS-Linux-Disk-Generic-Name-SNMP-custom > generic-active-service-custom > generic-active-service > generic-service | I23: OS-Linux-SNMP-Disk-Name | J23: os::linux::snmp::plugin | K23: storage | M23: $CENTREONPLUGINS$/centreon_linux_snmp.pl --plugin=os::linux::snmp::plugin --mode=storage --hostname=$HOSTADDRESS$ --snmp-version='2c' --snmp-community=******** --storage='$_SERVICEDISKNAME$' --name --warning-usage='$_SERVICEWARNING$' --critical-usage='$_SERVICECRITICAL$' | N23: Disque | O23: Linux by SNMP | P23: LLD vfs.fs (SNMP) | Q23: Natif | R23: Migrer (template natif) | S23: =IFERROR(IF(INDEX('Matrice templates services'!$Y$2:$Y$23,MATCH($G23,'Matrice templates services'!$A$2:$A$23,0))<>"",INDEX('Matrice templates services'!$Y$2:$Y$23,MATCH($G23,'Matrice templates services'!$A$2:$A$23,0)),INDEX('Matrice templates services'!$X$2:$X$23,MATCH($G23,'Matrice templates services'!$A$2:$A$23,0))),"") | U23: =IF(T23<>"",T23,IF(E23="Non","Ne pas migrer",S23))
A24: srv-lnx-web02 | B24: 10.0.10.12 | C24: Poller-DC1 | D24: HTTP-Response-Time | E24: Oui | F24: HG-Web | G24: App-Protocol-HTTP-Response-Time-custom | H24: App-Protocol-HTTP-Response-Time-custom > generic-active-service-custom > generic-active-service > generic-service | I24: App-Protocol-HTTP-Response | J24: apps::protocols::http::plugin | K24: response | M24: $CENTREONPLUGINS$/centreon_protocol_http.pl --plugin=apps::protocols::http::plugin --mode=response --hostname=$_SERVICEURLHOST$ --urlpath='/health' --ssl-opt='SSL_verify_mode => SSL_VERIFY_NONE' | N24: Web | O24: Website by Browser | P24: Scénario Web / web.page.get[] / item HTTP agent | Q24: Adapter | R24: Migrer (adapter) | S24: =IFERROR(IF(INDEX('Matrice templates services'!$Y$2:$Y$23,MATCH($G24,'Matrice templates services'!$A$2:$A$23,0))<>"",INDEX('Matrice templates services'!$Y$2:$Y$23,MATCH($G24,'Matrice templates services'!$A$2:$A$23,0)),INDEX('Matrice templates services'!$X$2:$X$23,MATCH($G24,'Matrice templates services'!$A$2:$A$23,0))),"") | U24: =IF(T24<>"",T24,IF(E24="Non","Ne pas migrer",S24))
A25: srv-lnx-web02 | B25: 10.0.10.12 | C25: Poller-DC1 | D25: Memory | E25: Oui | G25: OS-Linux-Memory-SNMP-custom | H25: OS-Linux-Memory-SNMP-custom > generic-active-service-custom > generic-active-service > generic-service | I25: OS-Linux-SNMP-Memory | J25: os::linux::snmp::plugin | K25: memory | M25: $CENTREONPLUGINS$/centreon_linux_snmp.pl --plugin=os::linux::snmp::plugin --mode=memory --hostname=$HOSTADDRESS$ --snmp-version='2c' --snmp-community=******** --warning-usage='$_SERVICEWARNING$' --critical-usage='$_SERVICECRITICAL$' | N25: Mémoire | O25: Linux by SNMP | P25: vm.memory.* (SNMP) | Q25: Natif | R25: Migrer (template natif) | S25: =IFERROR(IF(INDEX('Matrice templates services'!$Y$2:$Y$23,MATCH($G25,'Matrice templates services'!$A$2:$A$23,0))<>"",INDEX('Matrice templates services'!$Y$2:$Y$23,MATCH($G25,'Matrice templates services'!$A$2:$A$23,0)),INDEX('Matrice templates services'!$X$2:$X$23,MATCH($G25,'Matrice templates services'!$A$2:$A$23,0))),"") | U25: =IF(T25<>"",T25,IF(E25="Non","Ne pas migrer",S25))
A26: srv-lnx-web02 | B26: 10.0.10.12 | C26: Poller-DC1 | D26: Ping | E26: Oui | F26: HG-Linux | G26: Base-Ping-LAN | H26: Base-Ping-LAN > generic-active-service-custom > generic-active-service > generic-service | I26: App-Monitoring-Centreon-Ping | M26: $USER1$/check_icmp -H $HOSTADDRESS$ -n 5 -w 200,20% -c 400,50% | N26: Disponibilité | O26: ICMP Ping | P26: icmpping / icmppingloss / icmppingsec | Q26: Natif | R26: Migrer (template natif) | S26: =IFERROR(IF(INDEX('Matrice templates services'!$Y$2:$Y$23,MATCH($G26,'Matrice templates services'!$A$2:$A$23,0))<>"",INDEX('Matrice templates services'!$Y$2:$Y$23,MATCH($G26,'Matrice templates services'!$A$2:$A$23,0)),INDEX('Matrice templates services'!$X$2:$X$23,MATCH($G26,'Matrice templates services'!$A$2:$A$23,0))),"") | U26: =IF(T26<>"",T26,IF(E26="Non","Ne pas migrer",S26))
A27: srv-win-ad01 | B27: 10.0.20.11 | C27: Poller-DC1 | D27: Cpu | E27: Oui | G27: OS-Windows-Cpu-SNMP-custom | H27: OS-Windows-Cpu-SNMP-custom > generic-active-service-custom > generic-active-service > generic-service | I27: OS-Windows-SNMP-Cpu | J27: os::windows::snmp::plugin | K27: cpu | M27: $CENTREONPLUGINS$/centreon_windows_snmp.pl --plugin=os::windows::snmp::plugin --mode=cpu --hostname=$HOSTADDRESS$ --snmp-version='$_HOSTSNMPVERSION$' --snmp-community=******** | N27: CPU | O27: Windows by SNMP | P27: system.cpu.util (SNMP) | Q27: Natif | R27: Migrer (template natif) | S27: =IFERROR(IF(INDEX('Matrice templates services'!$Y$2:$Y$23,MATCH($G27,'Matrice templates services'!$A$2:$A$23,0))<>"",INDEX('Matrice templates services'!$Y$2:$Y$23,MATCH($G27,'Matrice templates services'!$A$2:$A$23,0)),INDEX('Matrice templates services'!$X$2:$X$23,MATCH($G27,'Matrice templates services'!$A$2:$A$23,0))),"") | U27: =IF(T27<>"",T27,IF(E27="Non","Ne pas migrer",S27))
A28: srv-win-ad01 | B28: 10.0.20.11 | C28: Poller-DC1 | D28: Disk-C | E28: Oui | G28: OS-Windows-Disk-Generic-Name-SNMP-custom | H28: OS-Windows-Disk-Generic-Name-SNMP-custom > generic-active-service-custom > generic-active-service > generic-service | I28: OS-Windows-SNMP-Storage | J28: os::windows::snmp::plugin | K28: storage | M28: $CENTREONPLUGINS$/centreon_windows_snmp.pl --plugin=os::windows::snmp::plugin --mode=storage --hostname=$HOSTADDRESS$ --snmp-version='$_HOSTSNMPVERSION$' --snmp-community=******** --storage='C:' | N28: Disque | O28: Windows by SNMP | P28: LLD vfs.fs (SNMP) | Q28: Natif | R28: Migrer (template natif) | S28: =IFERROR(IF(INDEX('Matrice templates services'!$Y$2:$Y$23,MATCH($G28,'Matrice templates services'!$A$2:$A$23,0))<>"",INDEX('Matrice templates services'!$Y$2:$Y$23,MATCH($G28,'Matrice templates services'!$A$2:$A$23,0)),INDEX('Matrice templates services'!$X$2:$X$23,MATCH($G28,'Matrice templates services'!$A$2:$A$23,0))),"") | U28: =IF(T28<>"",T28,IF(E28="Non","Ne pas migrer",S28))
A29: srv-win-ad01 | B29: 10.0.20.11 | C29: Poller-DC1 | D29: Service-NTDS | E29: Oui | G29: OS-Windows-Services-NRPE-custom | H29: OS-Windows-Services-NRPE-custom > generic-active-service-custom > generic-active-service > generic-service | I29: OS-Windows-NSClient-Services | M29: $USER1$/check_nrpe -H $HOSTADDRESS$ -p 5666 -c check_centreon_plugins -a 'os::windows::local::plugin' 'service' '--filter-name=NTDS' | N29: Services Windows | O29: Windows by Zabbix agent | P29: LLD service.discovery / service.info[] | Q29: Natif | R29: Migrer (template natif) | S29: =IFERROR(IF(INDEX('Matrice templates services'!$Y$2:$Y$23,MATCH($G29,'Matrice templates services'!$A$2:$A$23,0))<>"",INDEX('Matrice templates services'!$Y$2:$Y$23,MATCH($G29,'Matrice templates services'!$A$2:$A$23,0)),INDEX('Matrice templates services'!$X$2:$X$23,MATCH($G29,'Matrice templates services'!$A$2:$A$23,0))),"") | U29: =IF(T29<>"",T29,IF(E29="Non","Ne pas migrer",S29))
A30: srv-win-file01 | B30: 10.0.20.12 | C30: Poller-DC2 | D30: Cpu | E30: Oui | G30: OS-Windows-Cpu-SNMP-custom | H30: OS-Windows-Cpu-SNMP-custom > generic-active-service-custom > generic-active-service > generic-service | I30: OS-Windows-SNMP-Cpu | J30: os::windows::snmp::plugin | K30: cpu | M30: $CENTREONPLUGINS$/centreon_windows_snmp.pl --plugin=os::windows::snmp::plugin --mode=cpu --hostname=$HOSTADDRESS$ --snmp-version='$_HOSTSNMPVERSION$' --snmp-community=******** | N30: CPU | O30: Windows by SNMP | P30: system.cpu.util (SNMP) | Q30: Natif | R30: Migrer (template natif) | S30: =IFERROR(IF(INDEX('Matrice templates services'!$Y$2:$Y$23,MATCH($G30,'Matrice templates services'!$A$2:$A$23,0))<>"",INDEX('Matrice templates services'!$Y$2:$Y$23,MATCH($G30,'Matrice templates services'!$A$2:$A$23,0)),INDEX('Matrice templates services'!$X$2:$X$23,MATCH($G30,'Matrice templates services'!$A$2:$A$23,0))),"") | U30: =IF(T30<>"",T30,IF(E30="Non","Ne pas migrer",S30))
A31: srv-win-file01 | B31: 10.0.20.12 | C31: Poller-DC2 | D31: Disk-D | E31: Oui | G31: OS-Windows-Disk-Generic-Name-SNMP-custom | H31: OS-Windows-Disk-Generic-Name-SNMP-custom > generic-active-service-custom > generic-active-service > generic-service | I31: OS-Windows-SNMP-Storage | J31: os::windows::snmp::plugin | K31: storage | M31: $CENTREONPLUGINS$/centreon_windows_snmp.pl --plugin=os::windows::snmp::plugin --mode=storage --hostname=$HOSTADDRESS$ --snmp-version='$_HOSTSNMPVERSION$' --snmp-community=******** --storage='D:' | N31: Disque | O31: Windows by SNMP | P31: LLD vfs.fs (SNMP) | Q31: Natif | R31: Migrer (template natif) | S31: =IFERROR(IF(INDEX('Matrice templates services'!$Y$2:$Y$23,MATCH($G31,'Matrice templates services'!$A$2:$A$23,0))<>"",INDEX('Matrice templates services'!$Y$2:$Y$23,MATCH($G31,'Matrice templates services'!$A$2:$A$23,0)),INDEX('Matrice templates services'!$X$2:$X$23,MATCH($G31,'Matrice templates services'!$A$2:$A$23,0))),"") | U31: =IF(T31<>"",T31,IF(E31="Non","Ne pas migrer",S31))
A32: srv-win-file01 | B32: 10.0.20.12 | C32: Poller-DC2 | D32: Trap-Sauvegarde | E32: Oui | G32: Passive-Trap-Dummy | H32: Passive-Trap-Dummy > generic-service | I32: check_centreon_dummy | M32: $USER1$/check_dummy -o $ARG1$ -s $ARG2$ | N32: Passif / Dummy | P32: Item trapper (zabbix_sender) si encore utile | Q32: Abandonner | R32: Ne pas migrer | S32: =IFERROR(IF(INDEX('Matrice templates services'!$Y$2:$Y$23,MATCH($G32,'Matrice templates services'!$A$2:$A$23,0))<>"",INDEX('Matrice templates services'!$Y$2:$Y$23,MATCH($G32,'Matrice templates services'!$A$2:$A$23,0)),INDEX('Matrice templates services'!$X$2:$X$23,MATCH($G32,'Matrice templates services'!$A$2:$A$23,0))),"") | U32: =IF(T32<>"",T32,IF(E32="Non","Ne pas migrer",S32))
A33: sw-acc-02 | B33: 10.0.0.2 | C33: Poller-DC2 | D33: Environment | E33: Non | G33: Net-Cisco-Standard-Environment-SNMP-custom | H33: Net-Cisco-Standard-Environment-SNMP-custom > generic-active-service-custom > generic-active-service > generic-service | I33: Net-Cisco-Standard-SNMP-Environment | J33: network::cisco::standard::snmp::plugin | K33: environment | M33: $CENTREONPLUGINS$/centreon_cisco_standard_snmp.pl --plugin=network::cisco::standard::snmp::plugin --mode=environment --hostname=$HOSTADDRESS$ --snmp-community=******** | N33: Matériel | O33: (template constructeur SNMP) | P33: LLD capteurs / ventilateurs / alimentations | Q33: Natif | R33: Ne pas migrer | S33: =IFERROR(IF(INDEX('Matrice templates services'!$Y$2:$Y$23,MATCH($G33,'Matrice templates services'!$A$2:$A$23,0))<>"",INDEX('Matrice templates services'!$Y$2:$Y$23,MATCH($G33,'Matrice templates services'!$A$2:$A$23,0)),INDEX('Matrice templates services'!$X$2:$X$23,MATCH($G33,'Matrice templates services'!$A$2:$A$23,0))),"") | U33: =IF(T33<>"",T33,IF(E33="Non","Ne pas migrer",S33))
A34: sw-core-01 | B34: 10.0.0.1 | C34: Poller-DC1 | D34: Environment | E34: Oui | G34: Net-Cisco-Standard-Environment-SNMP-custom | H34: Net-Cisco-Standard-Environment-SNMP-custom > generic-active-service-custom > generic-active-service > generic-service | I34: Net-Cisco-Standard-SNMP-Environment | J34: network::cisco::standard::snmp::plugin | K34: environment | M34: $CENTREONPLUGINS$/centreon_cisco_standard_snmp.pl --plugin=network::cisco::standard::snmp::plugin --mode=environment --hostname=$HOSTADDRESS$ --snmp-community=******** | N34: Matériel | O34: (template constructeur SNMP) | P34: LLD capteurs / ventilateurs / alimentations | Q34: Natif | R34: Migrer (template natif) | S34: =IFERROR(IF(INDEX('Matrice templates services'!$Y$2:$Y$23,MATCH($G34,'Matrice templates services'!$A$2:$A$23,0))<>"",INDEX('Matrice templates services'!$Y$2:$Y$23,MATCH($G34,'Matrice templates services'!$A$2:$A$23,0)),INDEX('Matrice templates services'!$X$2:$X$23,MATCH($G34,'Matrice templates services'!$A$2:$A$23,0))),"") | U34: =IF(T34<>"",T34,IF(E34="Non","Ne pas migrer",S34))
A35: sw-core-01 | B35: 10.0.0.1 | C35: Poller-DC1 | D35: Traffic-Gi1/0/1 | E35: Oui | G35: Net-Cisco-Standard-Traffic-Generic-Name-SNMP-custom | H35: Net-Cisco-Standard-Traffic-Generic-Name-SNMP-custom > generic-active-service-custom > generic-active-service > generic-service | I35: Net-Cisco-Standard-SNMP-Traffic-Name | J35: network::cisco::standard::snmp::plugin | K35: interfaces | M35: $CENTREONPLUGINS$/centreon_cisco_standard_snmp.pl --plugin=network::cisco::standard::snmp::plugin --mode=interfaces --hostname=$HOSTADDRESS$ --snmp-community=******** --interface='GigabitEthernet1/0/1' --name | N35: Réseau | O35: (template constructeur SNMP) | P35: LLD net.if (SNMP) | Q35: Natif | R35: Migrer (template natif) | S35: =IFERROR(IF(INDEX('Matrice templates services'!$Y$2:$Y$23,MATCH($G35,'Matrice templates services'!$A$2:$A$23,0))<>"",INDEX('Matrice templates services'!$Y$2:$Y$23,MATCH($G35,'Matrice templates services'!$A$2:$A$23,0)),INDEX('Matrice templates services'!$X$2:$X$23,MATCH($G35,'Matrice templates services'!$A$2:$A$23,0))),"") | U35: =IF(T35<>"",T35,IF(E35="Non","Ne pas migrer",S35))
A36: ups-dc1 | B36: 10.0.0.50 | C36: Poller-DC1 | D36: Ping | E36: Oui | G36: Base-Ping-LAN | H36: Base-Ping-LAN > generic-active-service-custom > generic-active-service > generic-service | I36: App-Monitoring-Centreon-Ping | M36: $USER1$/check_icmp -H $HOSTADDRESS$ -n 5 -w 200,20% -c 400,50% | N36: Disponibilité | O36: ICMP Ping | P36: icmpping / icmppingloss / icmppingsec | Q36: Natif | R36: Migrer (template natif) | S36: =IFERROR(IF(INDEX('Matrice templates services'!$Y$2:$Y$23,MATCH($G36,'Matrice templates services'!$A$2:$A$23,0))<>"",INDEX('Matrice templates services'!$Y$2:$Y$23,MATCH($G36,'Matrice templates services'!$A$2:$A$23,0)),INDEX('Matrice templates services'!$X$2:$X$23,MATCH($G36,'Matrice templates services'!$A$2:$A$23,0))),"") | U36: =IF(T36<>"",T36,IF(E36="Non","Ne pas migrer",S36))

Sheet Croisé hôtes x tpl hôtes
A1: D = template appliqué directement, h = hérité
A2: Hôte | B2: generic-active-host | C2: generic-host | D2: generic-active-host-custom | E2: OS-Linux-SNMP-custom | F2: OS-Linux-SNMP | G2: App-Webserver-Apache-ServerStatus-custom | H2: OS-Windows-SNMP-custom | I2: Net-Cisco-Standard-SNMP-custom | J2: App-DB-MySQL-custom | K2: ERP-Applicatif | L2: OS-Windows-NSClient-05-NRPE-custom | M2: HW-Ups-Standard-Rfc1628-SNMP-custom
A3: srv-lnx-db01 | B3: h | C3: h | D3: h | E3: D | F3: h | J3: D
A4: srv-lnx-erp01 | B4: h | C4: h | D4: h | E4: D | F4: h | K4: D
A5: srv-lnx-web01 | B5: h | C5: h | D5: h | E5: D | F5: h | G5: D
A6: srv-lnx-web02 | B6: h | C6: h | D6: h | E6: D | F6: h | G6: D
A7: srv-win-ad01 | B7: h | C7: h | D7: h | H7: D | L7: D
A8: srv-win-file01 | B8: h | C8: h | D8: h | H8: D
A9: sw-acc-02 | B9: h | C9: h | D9: h | I9: D
A10: sw-core-01 | B10: h | C10: h | D10: h | I10: D
A11: ups-dc1 | B11: h | C11: h | D11: h | M11: D

Sheet Croisé hôtes x tpl services
A1: Nombre de services de l'hôte utilisant ce template
A2: Hôte | B2: OS-Linux-Memory-SNMP-custom | C2: Base-Ping-LAN | D2: OS-Linux-Cpu-SNMP-custom | E2: OS-Linux-Disk-Generic-Name-SNMP-custom | F2: ERP-Batch-Nocturne | G2: App-Webserver-Apache-Requests-custom | H2: App-Protocol-HTTP-Response-Time-custom | I2: OS-Windows-Cpu-SNMP-custom | J2: OS-Windows-Disk-Generic-Name-SNMP-custom | K2: Net-Cisco-Standard-Environment-SNMP-custom | L2: App-DB-MySQL-Connection-Time-custom | M2: OS-Linux-Process-Generic-SNMP-custom | N2: (aucun template) check_erp_batch | O2: OS-Windows-Services-NRPE-custom | P2: Passive-Trap-Dummy | Q2: Net-Cisco-Standard-Traffic-Generic-Name-SNMP-custom
A3: srv-lnx-db01 | B3: 1 | C3: 1 | D3: 1 | E3: 1 | L3: 1 | M3: 1
A4: srv-lnx-erp01 | B4: 1 | C4: 1 | D4: 1 | F4: 2 | N4: 1
A5: srv-lnx-web01 | B5: 2 | C5: 1 | D5: 1 | E5: 1 | G5: 1 | H5: 1
A6: srv-lnx-web02 | B6: 1 | C6: 1 | D6: 1 | E6: 1 | G6: 1 | H6: 1
A7: srv-win-ad01 | I7: 1 | J7: 1 | O7: 1
A8: srv-win-file01 | I8: 1 | J8: 1 | P8: 1
A9: sw-acc-02 | K9: 1
A10: sw-core-01 | K10: 1 | Q10: 1
A11: ups-dc1 | C11: 1

Sheet Commandes
A1: Commande | B1: Type | C1: Exécutable | D1: Plugin | E1: Mode | F1: Nb services | G1: Ligne de commande
A2: App-DB-MySQL-Connections | B2: check | C2: centreon_mysql.pl | D2: database::mysql::plugin | E2: connection-time | F2: 1 | G2: $CENTREONPLUGINS$/centreon_mysql.pl --plugin=database::mysql::plugin --mode=connection-time --host=$HOSTADDRESS$ --username='$_HOSTMYSQLUSERNAME$' --password=********
A3: App-Monitoring-Centreon-Ping | B3: check | C3: check_icmp | F3: 5 | G3: $USER1$/check_icmp -H $HOSTADDRESS$ -n $_SERVICEPACKETNUMBER$ -w $_SERVICEWARNING$ -c $_SERVICECRITICAL$
A4: App-Protocol-HTTP-Response | B4: check | C4: centreon_protocol_http.pl | D4: apps::protocols::http::plugin | E4: response | F4: 2 | G4: $CENTREONPLUGINS$/centreon_protocol_http.pl --plugin=apps::protocols::http::plugin --mode=response --hostname=$_SERVICEURLHOST$ --urlpath='$_SERVICEURLPATH$' --ssl-opt='SSL_verify_mode => SSL_VERIFY_NONE'
A5: App-Webserver-Apache-Requests | B5: check | C5: centreon_apache_serverstatus.pl | D5: apps::apache::serverstatus::plugin | E5: requests | F5: 2 | G5: $CENTREONPLUGINS$/centreon_apache_serverstatus.pl --plugin=apps::apache::serverstatus::plugin --mode=requests --hostname=$HOSTADDRESS$
